Workbook

Sheet Como usar
B2: PLANILHA DE AVALIAÇÃO — MODELO QUANTITATIVO
B4: O QUE MUDOU
B5: As perguntas | C5: São as mesmas da planilha antiga. Nenhuma pergunta nova, exceto A6 (inconsistência plantada), que entra no lugar de 'Resposta dos concorrentes' — item que ficou 89% zerado no PS 2026-1S e nem estava na Base.
B6: A escala | C6: Toda nota agora é 0, 1, 2 ou 3. Acabaram os 0,7 / 1,2 / 2,8. Cada nível tem uma frase que o descreve na aba 'Base avaliação'. Se você não consegue apontar a frase, você não pode dar aquela nota.
B7: Os pesos | C7: Comunicação 30 · Raciocínio 25 · Acurácia 25 · Entrega 10 · Vídeo 10. O peso agora está no bloco, não escondido no teto de cada pergunta.
B8: A trava | C8: A célula só aceita 0/1/2/3. No PS passado, 8 das 27 linhas tinham nota acima do teto do critério.
B9: O peso do vídeo | C9: 0.1
B10: R3 e E4 | C10: Reescritos para premiar RELEVÂNCIA, não volume. Antes, análise extra tangencial pontuava 2 e fazer o pedido direito pontuava 0 — invertido. Agora tangente é 0 e entregar o pedido completo é 1. Em E4, contagem de gráficos saiu: o que vale é o recurso sustentar uma afirmação.
B12: AS 5 REGRAS
B13: 1. Evidência obrigatória | C13: Ao lado da nota de cada bloco há uma coluna de evidência. Escreva o número do slide ou a minutagem do vídeo. É isso que torna a nota revisável e permite dar feedback ao candidato depois. NA PRÁTICA: preencha ao menos para todo 3 e todo 0 são as notas que afirmam algo forte e que o 2º avaliador contesta. O 2 é o meio-termo e raramente vira discussão. Veja a linha 6 (Modelo) para o formato.
B14: 2. Corrija por critério | C14: Avalie TODOS os candidatos no C1, depois todos no C2, e assim por diante. Nunca candidato por candidato. Comparar 27 respostas da mesma pergunta lado a lado é muito mais consistente e é o que evita que uma boa impressão geral contamine as 20 notas.
B15: 3. Dois avaliadores | C15: Todo candidato precisa de 2 avaliações independentes. No PS 2026-1S só 37% tiveram. Se a diferença entre as duas notas finais passar de 1,0, a aba Consolidado acende alerta: vai para conversa de calibração ou terceiro avaliador.
B16: 4. Calibre antes de abrir | C16: Antes do PS começar: peguem 3 entregas do PS anterior (uma boa, uma média, uma ruim), todo mundo avalia, comparem e discutam as divergências. Uma hora de reunião. É a maior alavanca de consistência que existe e não custa nada.
B17: 5. Corte definido antes | C17: Número de vagas e nota mínima decididos ANTES de ver as notas. Desempate escrito: 1º acurácia · 2º comunicação · 3º entrevista.
B19: A NOTA QUANDO DUAS PESSOAS CORRIGEM
B20: Sim, é a média | C20: Se um avaliador dá 6,0 e o outro 7,0, a nota do candidato é 6,50. A aba Consolidado faz isso sozinha (AVERAGEIF por nome). Não arredonde na mão.
B21: Onde a vírgula pode aparecer | C21: Só na MÉDIA ENTRE PESSOAS, nunca dentro da cabeça de uma pessoa. Cada avaliador só digita 0, 1, 2 ou 3 — e a célula não aceita outra coisa. O 6,50 é o resultado de duas leituras independentes; o antigo 6,5 era uma pessoa sentindo que valia meio ponto. Mesmo número, confiabilidade completamente diferente.
B22: Quando a média NÃO vale | C22: Se a diferença passar de 1,0 (ex.: 5,8 e 7,2), a aba acende alerta e a média fica suspensa. Média de duas leituras que discordam muito não é consenso, é um número inventado no meio. Nesse caso: conversem, releiam juntos o critério que divergiu e refaçam — ou chamem um terceiro.
B23: Por que 1,0 é o limite | C23: Com escala de 0 a 3 e 20 critérios, dois avaliadores calibrados raramente passam de 1 ponto de diferença na nota final. Se passou, quase sempre é um critério só sendo lido de dois jeitos — e é isso que a conversa resolve. As colunas 'Nota aval. 1' e 'Nota aval. 2' mostram as duas notas lado a lado.
B25: ELEGIBILIDADE (estágio / intercâmbio / formatura)
B26: Não é eliminatório | C26: Conforme o diretor: é um warning, não um corte. Por isso NÃO entra na nota e NÃO tem peso. Fica só na aba Consolidado.
B27: Dois níveis | C27: 🔴 EVASÃO — sai do ar em até 2 semestres (intercâmbio confirmado, formatura próxima). 🟡 CARGA — continua, mas com menos tempo (estagiando agora, estágio começando no ano). Estagiar não é ir embora: é ter menos tempo. São riscos diferentes.
B28: Onde ela morde | C28: A flag não soma nem subtrai ponto e nunca elimina. Ela (i) obriga uma pergunta específica na entrevista e (ii) só desempata entre candidatos a menos de 0,3 ponto um do outro.
B29: Horas por semana | C29: VOLTEM COM ESSA PERGUNTA NO FORMULÁRIO. 2025.2 perguntava quantas horas o candidato dedicaria (todos responderam: mediana 8h, variando de 4 a 40) e ela sumiu em 2026.1. Tem variância real e mede o risco de CARGA muito melhor que 'estagiando sim/não' — porque os 13 aprovados de 2025.2 declararam plano de estágio, TODOS os 13. Uma flag que dispara em 100% da lista não separa nada.
B30: O que os dados já dizem | C30: Dos 13 aprovados em 2025.2, 4 apareceram como avaliadores em 2026.1 (Gustavo, Fred, Victor, AnaJu) — com planos de estágio variados, sem padrão. O único com formatura em 2026 não reaparece. É indício fraco (n=1), mas aponta para FORMATURA como a variável de risco real, não estágio. Por isso 🔴 EVASÃO e 🟡 CARGA são separados.
B31: Medir | C31: Registrem a flag de cada aprovado. Daqui a 2 ou 3 PS, cruzem com quem de fato continuou no clube. Aí vocês saberão se a hipótese é verdadeira — hoje ninguém sabe.
B33: O CASE E A IA
B34: O problema | C34: 3 dias em casa: acurácia deixa de discriminar. No PS 2026-1S, antes da IA virar padrão, 62% dos candidatos já tiravam ≥80% do teto em 'Loja 5' e 65% em 'SG&A'. Peso sem variância não muda ranking.
B35: Erro plantado (A6) | C35: Coloquem uma inconsistência de propósito no material: a DRE não fecha por X, ou o enunciado contradiz a tabela anexa. IA aceita o input como verdade e segue. Custa 10 minutos montando o case e é o melhor discriminador por esforço investido.
B36: Premissa ausente | C36: Não deem o critério de rateio do SG&A entre lojas. Aí não existe 'a resposta certa': pontua-se se declarou a premissa, se a carregou até a recomendação sem se contradizer e se testou outra.
B37: Propriedade na ENTREVISTA | C37: Não tente detectar IA no take-home. Nos primeiros 10 minutos da entrevista, o candidato refaz UMA conta da própria entrega, ao vivo, com um parâmetro alterado. Quem montou o modelo resolve em 3 minutos. Registre em Consolidado!K como OK / Não OK.

Sheet Base avaliação
B2: BASE DE AVALIAÇÃO — cada nível tem uma descrição. Sem descrição apontada, a nota não vale.
B4: COMUNICAÇÃO & ESTRUTURA — 30 pontos de 100
B5: C1 | C5: 10 pts | D5: A comunicação está clara e direto ao ponto.
C6: 3 | D6: A recomendação está escrita em UMA frase, nos 2 primeiros slides, com o número que a sustenta.
C7: 2 | D7: A recomendação é explícita e clara, mas só aparece depois da metade da entrega.
C8: 1 | D8: Dá pra inferir a recomendação, mas ela não está escrita em lugar nenhum.
C9: 0 | D9: Não há recomendação, ou há duas incompatíveis entre si.
D10: TESTE OPERACIONAL: Aponte o slide e a frase. Não conseguiu apontar? Não é 3.
B12: C2 | C12: 8 pts | D12: O desafio apresenta um formato que poderia ser apresentado a um cliente real.
C13: 3 | D13: Documento fechado (capa, estrutura, apêndice), sem rascunho visível. Um cliente receberia como está.
C14: 2 | D14: Estruturado, mas com pontas soltas: conta solta, slide inacabado, formatação inconsistente.
C15: 1 | D15: Responde as perguntas, mas em formato de lista ou rascunho.
C16: 0 | D16: Foto de papel, texto corrido no e-mail, ou arquivo sem estrutura nenhuma.
D17: TESTE OPERACIONAL: Você mandaria esse arquivo, sem editar nada, pro cliente do seu projeto?
B19: C3 | C19: 7 pts | D19: A apresentação apresenta um bom storytelling e envolve o leitor.
C20: 3 | D20: Lendo só os títulos, na ordem, a história fecha sozinha: contexto -> problema -> análise -> recomendação -> riscos.
C21: 2 | D21: A sequência é lógica, com 1 ou 2 saltos que obrigam o leitor a voltar.
C22: 1 | D22: Os blocos existem, mas soltos — um não puxa o outro.
C23: 0 | D23: Ordem aleatória, ou é só uma lista de respostas às perguntas.
D24: TESTE OPERACIONAL: Leia SÓ os títulos em voz alta. Se a recomendação não aparecer, é no máximo 1.
B26: C4 | C26: 5 pts | D26: O trabalho está visualmente bonito.
C27: 3 | D27: Padrão único de fonte, cor e alinhamento em toda a entrega. Nenhum slide com parágrafo corrido.
C28: 2 | D28: Consistente, com até 2 slides fora do padrão.
C29: 1 | D29: Formatação improvisada, mas legível.
C30: 0 | D30: Ilegível, desalinhado, ou é texto corrido.
D31: TESTE OPERACIONAL: Conte os slides fora do padrão. É uma contagem, não uma impressão.
B34: RACIOCÍNIO DE NEGÓCIO — 25 pontos de 100
B35: R1 | C35: 8 pts | D35: Sua recomendação leva em consideração ambas as partes qualitativas e quantitativas do case.
C36: 3 | D36: A recomendação cita o número que a sustenta E a razão de negócio; as duas partes se apoiam.
C37: 2 | D37: Cita as duas, mas uma é decorativa — o número não sustenta de fato a decisão.
C38: 1 | D38: Só quantitativa (número sem porquê) ou só qualitativa (opinião sem número).
C39: 0 | D39: Não há recomendação, ou ela contraria os próprios números apresentados.
D40: TESTE OPERACIONAL: Tape o número: a recomendação ainda se sustenta? Tape o argumento: ainda se sustenta?
B42: R2 | C42: 7 pts | D42: O trabalho apresenta uma discussão rica com diversos pontos de vista sobre a expansão.
C43: 3 | D43: Apresenta ao menos 2 caminhos, compara com critério explícito e justifica o que descartou.
C44: 2 | D44: Cita alternativas, mas não compara — escolhe sem justificar.
C45: 1 | D45: Menciona que existem alternativas, sem desenvolver nenhuma.
C46: 0 | D46: Caminho único, sem discussão.
D47: TESTE OPERACIONAL: Ele descartou alguma coisa por escrito? Se não descartou nada, não discutiu.
B49: R3 | C49: 5 pts | D49: Foi além do pedido e trouxe análises interessantes.
...

Sheet Avaliação
B2: AVALIAÇÃO — uma linha por candidato POR AVALIADOR. Cada candidato deve aparecer 2 vezes.
B4: Cada nome aparece 2 vezes pra terem 2 avaliadores por pessoa! | K4: COMUNICAÇÃO & ESTRUTURA (30) | P4: RACIOCÍNIO DE NEGÓCIO (25) | U4: ACURÁCIA TÉCNICA (25) | AB4: ENTREGA (CHECKLIST) (10) | AF4: VÍDEO DO FORMULÁRIO (10)
A5: # | B5: E-mail | C5: Candidato(a) | D5: Avaliador | E5: NOTA FINAL | F5: Comunic. /30 | G5: Racioc. /25 | H5: Acurácia /25 | I5: Entrega /10 | J5: Vídeo /10 | K5: C1 | L5: C2 | M5: C3 | N5: C4 | O5: Evidência — Comunicação | P5: R1 | Q5: R2 | R5: R3 | S5: R4 | T5: Evidência — Raciocínio | U5: A1 | V5: A2 | W5: A3 | X5: A4 | Y5: A5 | Z5: A6 | AA5: Evidência — Acurácia | AB5: E1 | AC5: E2 | AD5: E3 | AE5: E4 | AF5: V1 | AG5: V2 | AH5: Evidência — Vídeo | AI5: Comentário geral
C6: Modelo (entrega nota máxima) | E6: =IF(COUNT(K6:AG6)=0,"",ROUND((F6+G6+H6+I6+J6)/10,2)) -> 10 | F6: =IF(COUNT(K6:AG6)=0,"",(K6*10+L6*8+M6*7+N6*5)/3) -> 30 | G6: =IF(COUNT(K6:AG6)=0,"",(P6*8+Q6*7+R6*5+S6*5)/3) -> 25 | H6: =IF(COUNT(K6:AG6)=0,"",(U6*6+V6*6+W6*4+X6*3+Y6*3+Z6*3)/3) -> 25 | I6: =IF(COUNT(K6:AG6)=0,"",AB6*3+AC6*2+AD6*2+AE6*1) -> 10 | J6: =IF(COUNT(K6:AG6)=0,"",(AF6*5+AG6*5)/3) -> 10 | K6: 3 | L6: 3 | M6: 3 | N6: 3 | O6: C1=3: slide 2, "Fechar a Loja 5 e migrar p/ B2B eleva o EBITDA em R$ 4,1mi" · C3=3: lendo só os títulos (slides 1-9) a história fecha · C4=3: padrão único em toda a entrega | P6: 3 | Q6: 3 | R6: 3 | S6: 3 | T6: R1=3: slide 2 liga o número ao argumento de negócio · R2=3: compara fechar vs. reformar no slide 7 e justifica o descarte · R3=3: análise de sazonalidade (slide 10) mudou a recomendação | U6: 3 | V6: 3 | W6: 3 | X6: 3 | Y6: 3 | Z6: 3 | AA6: A1=3: Excel, aba "Loja 5", D12-D18 · A2=3: aba "SG&A", C4-C11 · A6=3: apontou no slide 3 que a DRE não fecha por R$ 120k e explicou como tratou | AB6: 1 | AC6: 1 | AD6: 1 | AE6: 3 | AF6: 3 | AG6: 3 | AH6: V1=3: fala solta o vídeo inteiro, sem ler · V2=3: cita o projeto X aos 2:15
B7: g278083@dac.unicamp.br | C7: Gabrielle Cristofani do Rosario | D7: victor | E7: =IF(COUNT(K7:AG7)=0,"",ROUND((F7+G7+H7+I7+J7)/10,2)) -> 0.67 | F7: =IF(COUNT(K7:AG7)=0,"",(K7*10+L7*8+M7*7+N7*5)/3) -> 0 | G7: =IF(COUNT(K7:AG7)=0,"",(P7*8+Q7*7+R7*5+S7*5)/3) -> 0 | H7: =IF(COUNT(K7:AG7)=0,"",(U7*6+V7*6+W7*4+X7*3+Y7*3+Z7*3)/3) -> 0 | I7: =IF(COUNT(K7:AG7)=0,"",AB7*3+AC7*2+AD7*2+AE7*1) -> 0 | J7: =IF(COUNT(K7:AG7)=0,"",(AF7*5+AG7*5)/3) -> 6.6666667 | AF7: 2 | AG7: 2 | AI7: v2 talvez seja 3
B8: b309603@dac.unicamp.br | C8: Bruno Heberth Oliveira Bastos | D8: victor | E8: =IF(COUNT(K8:AG8)=0,"",ROUND((F8+G8+H8+I8+J8)/10,2)) -> 0.67 | F8: =IF(COUNT(K8:AG8)=0,"",(K8*10+L8*8+M8*7+N8*5)/3) -> 0 | G8: =IF(COUNT(K8:AG8)=0,"",(P8*8+Q8*7+R8*5+S8*5)/3) -> 0 | H8: =IF(COUNT(K8:AG8)=0,"",(U8*6+V8*6+W8*4+X8*3+Y8*3+Z8*3)/3) -> 0 | I8: =IF(COUNT(K8:AG8)=0,"",AB8*3+AC8*2+AD8*2+AE8*1) -> 0 | J8: =IF(COUNT(K8:AG8)=0,"",(AF8*5+AG8*5)/3) -> 6.6666667 | AF8: 3 | AG8: 1 | AI8: É da Adm n dá
B9: j309764@dac.unicamp.br | C9: João Pedro Mendes Stama | D9: victor | E9: =IF(COUNT(K9:AG9)=0,"",ROUND((F9+G9+H9+I9+J9)/10,2)) -> 0.83 | F9: =IF(COUNT(K9:AG9)=0,"",(K9*10+L9*8+M9*7+N9*5)/3) -> 0 | G9: =IF(COUNT(K9:AG9)=0,"",(P9*8+Q9*7+R9*5+S9*5)/3) -> 0 | H9: =IF(COUNT(K9:AG9)=0,"",(U9*6+V9*6+W9*4+X9*3+Y9*3+Z9*3)/3) -> 0 | I9: =IF(COUNT(K9:AG9)=0,"",AB9*3+AC9*2+AD9*2+AE9*1) -> 0 | J9: =IF(COUNT(K9:AG9)=0,"",(AF9*5+AG9*5)/3) -> 8.3333333 | AF9: 3 | AG9: 2 | AI9: N passaria fez o gmat na cama mas parece legal
B10: r238449@dac.unicamp.br | C10: Rafael Ponciano Rodrigues dos Santos | D10: luis | E10: =IF(COUNT(K10:AG10)=0,"",ROUND((F10+G10+H10+I10+J10)/10,2)) -> 0.83 | F10: =IF(COUNT(K10:AG10)=0,"",(K10*10+L10*8+M10*7+N10*5)/3) -> 0 | G10: =IF(COUNT(K10:AG10)=0,"",(P10*8+Q10*7+R10*5+S10*5)/3) -> 0 | H10: =IF(COUNT(K10:AG10)=0,"",(U10*6+V10*6+W10*4+X10*3+Y10*3+Z10*3)/3) -> 0 | I10: =IF(COUNT(K10:AG10)=0,"",AB10*3+AC10*2+AD10*2+AE10*1) -> 0 | J10: =IF(COUNT(K10:AG10)=0,"",(AF10*5+AG10*5)/3) -> 8.3333333 | AF10: 3 | AG10: 2 | AI10: n falou nada do clube e tem um canal de 40 k de inscritos👍
B11: enzo.gag17@gmail.com | C11: Enzo Chofakian Gagliardi | D11: victor | E11: =IF(COUNT(K11:AG11)=0,"",ROUND((F11+G11+H11+I11+J11)/10,2)) -> 0.67 | F11: =IF(COUNT(K11:AG11)=0,"",(K11*10+L11*8+M11*7+N11*5)/3) -> 0 | G11: =IF(COUNT(K11:AG11)=0,"",(P11*8+Q11*7+R11*5+S11*5)/3) -> 0 | H11: =IF(COUNT(K11:AG11)=0,"",(U11*6+V11*6+W11*4+X11*3+Y11*3+Z11*3)/3) -> 0 | I11: =IF(COUNT(K11:AG11)=0,"",AB11*3+AC11*2+AD11*2+AE11*1) -> 0 | J11: =IF(COUNT(K11:AG11)=0,"",(AF11*5+AG11*5)/3) -> 6.6666667 | AF11: 2 | AG11: 2 | AI11: ok
B12: e278588@dac.unicamp.br | C12: Enrico Tristão e Mello de Oliveira | D12: victor | E12: =IF(COUNT(K12:AG12)=0,"",ROUND((F12+G12+H12+I12+J12)/10,2)) -> 0.5 | F12: =IF(COUNT(K12:AG12)=0,"",(K12*10+L12*8+M12*7+N12*5)/3) -> 0 | G12: =IF(COUNT(K12:AG12)=0,"",(P12*8+Q12*7+R12*5+S12*5)/3) -> 0 | H12: =IF(COUNT(K12:AG12)=0,"",(U12*6+V12*6+W12*4+X12*3+Y12*3+Z12*3)/3) -> 0 | I12: =IF(COUNT(K12:AG12)=0,"",AB12*3+AC12*2+AD12*2+AE12*1) -> 0 | J12: =IF(COUNT(K12:AG12)=0,"",(AF12*5+AG12*5)/3) -> 5 | AF12: 2 | AG12: 1 | AI12: N falou nada do clube só do mercado
B13: e221509@dac.unicamp.br | C13: Eduardo Alves Henrique | D13: victor | E13: =IF(COUNT(K13:AG13)=0,"",ROUND((F13+G13+H13+I13+J13)/10,2)) -> 0.33 | F13: =IF(COUNT(K13:AG13)=0,"",(K13*10+L13*8+M13*7+N13*5)/3) -> 0 | G13: =IF(COUNT(K13:AG13)=0,"",(P13*8+Q13*7+R13*5+S13*5)/3) -> 0 | H13: =IF(COUNT(K13:AG13)=0,"",(U13*6+V13*6+W13*4+X13*3+Y13*3+Z13*3)/3) -> 0 | I13: =IF(COUNT(K13:AG13)=0,"",AB13*3+AC13*2+AD13*2+AE13*1) -> 0 | J13: =IF(COUNT(K13:AG13)=0,"",(AF13*5+AG13*5)/3) -> 3.3333333 | AF13: 2 | AG13: 0 | AI13: Só falou que queria o CCU pra pegar cargo e ter no currículo
B14: l304532@dac.unicamp.br | C14: Leandra Cunha de Souza | D14: victor | E14: =IF(COUNT(K14:AG14)=0,"",ROUND((F14+G14+H14+I14+J14)/10,2)) -> 0.67 | F14: =IF(COUNT(K14:AG14)=0,"",(K14*10+L14*8+M14*7+N14*5)/3) -> 0 | G14: =IF(COUNT(K14:AG14)=0,"",(P14*8+Q14*7+R14*5+S14*5)/3) -> 0 | H14: =IF(COUNT(K14:AG14)=0,"",(U14*6+V14*6+W14*4+X14*3+Y14*3+Z14*3)/3) -> 0 | I14: =IF(COUNT(K14:AG14)=0,"",AB14*3+AC14*2+AD14*2+AE14*1) -> 0 | J14: =IF(COUNT(K14:AG14)=0,"",(AF14*5+AG14*5)/3) -> 6.6666667 | AF14: 2 | AG14: 2 | AI14: Mid, muitas experiencias mas todas na escola, achei confusa a resposta só saiu citando coisas q fez
B15: v188630@dac.unicamp.br | C15: Vagner Ássimos Gomes Carlos Filho | D15: victor | E15: =IF(COUNT(K15:AG15)=0,"",ROUND((F15+G15+H15+I15+J15)/10,2)) -> 0.83 | F15: =IF(COUNT(K15:AG15)=0,"",(K15*10+L15*8+M15*7+N15*5)/3) -> 0 | G15: =IF(COUNT(K15:AG15)=0,"",(P15*8+Q15*7+R15*5+S15*5)/3) -> 0 | H15: =IF(COUNT(K15:AG15)=0,"",(U15*6+V15*6+W15*4+X15*3+Y15*3+Z15*3)/3) -> 0 | I15: =IF(COUNT(K15:AG15)=0,"",AB15*3+AC15*2+AD15*2+AE15*1) -> 0 | J15: =IF(COUNT(K15:AG15)=0,"",(AF15*5+AG15*5)/3) -> 8.3333333 | AF15: 2 | AG15: 3 | AI15: Falou das palestras, n sei se tava lendo ou só olhado pra camera mas falou bem ent talvez seja 3
B16: m277865@dac.unicamp.br | C16: Mariana Nunes Galvão Sant'Anna | D16: luis | E16: =IF(COUNT(K16:AG16)=0,"",ROUND((F16+G16+H16+I16+J16)/10,2)) -> 0.83 | F16: =IF(COUNT(K16:AG16)=0,"",(K16*10+L16*8+M16*7+N16*5)/3) -> 0 | G16: =IF(COUNT(K16:AG16)=0,"",(P16*8+Q16*7+R16*5+S16*5)/3) -> 0 | H16: =IF(COUNT(K16:AG16)=0,"",(U16*6+V16*6+W16*4+X16*3+Y16*3+Z16*3)/3) -> 0 | I16: =IF(COUNT(K16:AG16)=0,"",AB16*3+AC16*2+AD16*2+AE16*1) -> 0 | J16: =IF(COUNT(K16:AG16)=0,"",(AF16*5+AG16*5)/3) -> 8.3333333 | AF16: 3 | AG16: 2 | AI16: motivo genérico
B17: a266739@dac.unicamp.br | C17: Aslan Rodrigues Maia | D17: Ferro | E17: =IF(COUNT(K17:AG17)=0,"",ROUND((F17+G17+H17+I17+J17)/10,2)) -> 0.5 | F17: =IF(COUNT(K17:AG17)=0,"",(K17*10+L17*8+M17*7+N17*5)/3) -> 0 | G17: =IF(COUNT(K17:AG17)=0,"",(P17*8+Q17*7+R17*5+S17*5)/3) -> 0 | H17: =IF(COUNT(K17:AG17)=0,"",(U17*6+V17*6+W17*4+X17*3+Y17*3+Z17*3)/3) -> 0 | I17: =IF(COUNT(K17:AG17)=0,"",AB17*3+AC17*2+AD17*2+AE17*1) -> 0 | J17: =IF(COUNT(K17:AG17)=0,"",(AF17*5+AG17*5)/3) -> 5 | AF17: 1 | AG17: 2 | AI17: TIrou 2/3 do Gmat, e falou um pouco travado no vídeo, mas foi bem (não é bixo)
B18: j278641@dac.unicamp.br | C18: João Gabriel de Oliveira Morcelli | D18: Ferro | E18: =IF(COUNT(K18:AG18)=0,"",ROUND((F18+G18+H18+I18+J18)/10,2)) -> 0.83 | F18: =IF(COUNT(K18:AG18)=0,"",(K18*10+L18*8+M18*7+N18*5)/3) -> 0 | G18: =IF(COUNT(K18:AG18)=0,"",(P18*8+Q18*7+R18*5+S18*5)/3) -> 0 | H18: =IF(COUNT(K18:AG18)=0,"",(U18*6+V18*6+W18*4+X18*3+Y18*3+Z18*3)/3) -> 0 | I18: =IF(COUNT(K18:AG18)=0,"",AB18*3+AC18*2+AD18*2+AE18*1) -> 0 | J18: =IF(COUNT(K18:AG18)=0,"",(AF18*5+AG18*5)/3) -> 8.3333333 | AF18: 3 | AG18: 2 | AI18: 2/3 Gmat, fez no final sem energia, cara foi resiliente, falou muito bem no vídeo
... B27: i253464@dac.unicamp.br | C27: Isadora Kluge Dorigan | D27: Proc | E27: =IF(COUNT(K27:AG27)=0,"",ROUND((F27+G27+H27+I27+J27)/10,2)) -> 0.83 | F27: =IF(COUNT(K27:AG27)=0,"",(K27*10+L27*8+M27*7+N27*5)/3) -> 0 | G27: =IF(COUNT(K27:AG27)=0,"",(P27*8+Q27*7+R27*5+S27*5)/3) -> 0 | H27: =IF(COUNT(K27:AG27)=0,"",(U27*6+V27*6+W27*4+X27*3+Y27*3+Z27*3)/3) -> 0 | I27: =IF(COUNT(K27:AG27)=0,"",AB27*3+AC27*2+AD27*2+AE27*1) -> 0 | J27: =IF(COUNT(K27:AG27)=0,"",(AF27*5+AG27*5)/3) -> 8.3333333 | AF27: 2 | AG27: 3 | AI27: 43% do GMAT. Senti que lia. Falou bem. Trajetória sólida.
B28: SEGUNDO AVALIADOR | C28: SEGUNDO AVALIADOR | E28: =IF(COUNT(K28:AG28)=0,"",ROUND((F28+G28+H28+I28+J28)/10,2)) | F28: =IF(COUNT(K28:AG28)=0,"",(K28*10+L28*8+M28*7+N28*5)/3) | G28: =IF(COUNT(K28:AG28)=0,"",(P28*8+Q28*7+R28*5+S28*5)/3) | H28: =IF(COUNT(K28:AG28)=0,"",(U28*6+V28*6+W28*4+X28*3+Y28*3+Z28*3)/3) | I28: =IF(COUNT(K28:AG28)=0,"",AB28*3+AC28*2+AD28*2+AE28*1) | J28: =IF(COUNT(K28:AG28)=0,"",(AF28*5+AG28*5)/3)
B29: g278083@dac.unicamp.br | C29: Gabrielle Cristofani do Rosario | D29: Fred | E29: =IF(COUNT(K29:AG29)=0,"",ROUND((F29+G29+H29+I29+J29)/10,2)) -> 0.83 | F29: =IF(COUNT(K29:AG29)=0,"",(K29*10+L29*8+M29*7+N29*5)/3) -> 0 | G29: =IF(COUNT(K29:AG29)=0,"",(P29*8+Q29*7+R29*5+S29*5)/3) -> 0 | H29: =IF(COUNT(K29:AG29)=0,"",(U29*6+V29*6+W29*4+X29*3+Y29*3+Z29*3)/3) -> 0 | I29: =IF(COUNT(K29:AG29)=0,"",AB29*3+AC29*2+AD29*2+AE29*1) -> 0 | J29: =IF(COUNT(K29:AG29)=0,"",(AF29*5+AG29*5)/3) -> 8.3333333 | AF29: 3 | AG29: 2 | AI29: feagri 3° ano de curso, falou bem, mas foi generica em falar de consultoria
B30: b309603@dac.unicamp.br | C30: Bruno Heberth Oliveira Bastos | D30: Fred | E30: =IF(COUNT(K30:AG30)=0,"",ROUND((F30+G30+H30+I30+J30)/10,2)) -> 0.67 | F30: =IF(COUNT(K30:AG30)=0,"",(K30*10+L30*8+M30*7+N30*5)/3) -> 0 | G30: =IF(COUNT(K30:AG30)=0,"",(P30*8+Q30*7+R30*5+S30*5)/3) -> 0 | H30: =IF(COUNT(K30:AG30)=0,"",(U30*6+V30*6+W30*4+X30*3+Y30*3+Z30*3)/3) -> 0 | I30: =IF(COUNT(K30:AG30)=0,"",AB30*3+AC30*2+AD30*2+AE30*1) -> 0 | J30: =IF(COUNT(K30:AG30)=0,"",(AF30*5+AG30*5)/3) -> 6.6666667 | AF30: 3 | AG30: 1
B31: j309764@dac.unicamp.br | C31: JOÃO PEDRO STAMA | D31: Fred | E31: =IF(COUNT(K31:AG31)=0,"",ROUND((F31+G31+H31+I31+J31)/10,2)) -> 0.5 | F31: =IF(COUNT(K31:AG31)=0,"",(K31*10+L31*8+M31*7+N31*5)/3) -> 0 | G31: =IF(COUNT(K31:AG31)=0,"",(P31*8+Q31*7+R31*5+S31*5)/3) -> 0 | H31: =IF(COUNT(K31:AG31)=0,"",(U31*6+V31*6+W31*4+X31*3+Y31*3+Z31*3)/3) -> 0 | I31: =IF(COUNT(K31:AG31)=0,"",AB31*3+AC31*2+AD31*2+AE31*1) -> 0 | J31: =IF(COUNT(K31:AG31)=0,"",(AF31*5+AG31*5)/3) -> 5 | AF31: 1 | AG31: 2 | AI31: colou no gmat
B32: r238449@dac.unicamp.br | C32: Rafael Ponciano Rodrigues dos Santos | D32: Fred | E32: =IF(COUNT(K32:AG32)=0,"",ROUND((F32+G32+H32+I32+J32)/10,2)) -> 0.83 | F32: =IF(COUNT(K32:AG32)=0,"",(K32*10+L32*8+M32*7+N32*5)/3) -> 0 | G32: =IF(COUNT(K32:AG32)=0,"",(P32*8+Q32*7+R32*5+S32*5)/3) -> 0 | H32: =IF(COUNT(K32:AG32)=0,"",(U32*6+V32*6+W32*4+X32*3+Y32*3+Z32*3)/3) -> 0 | I32: =IF(COUNT(K32:AG32)=0,"",AB32*3+AC32*2+AD32*2+AE32*1) -> 0 | J32: =IF(COUNT(K32:AG32)=0,"",(AF32*5+AG32*5)/3) -> 8.3333333 | AF32: 3 | AG32: 2 | AI32: Falou bem no vídeo (levemente robótico) e mandou bem no gmat
B33: enzo.gag17@gmail.com | C33: Enzo Chofakian Gagliardi | D33: Ferro | E33: =IF(COUNT(K33:AG33)=0,"",ROUND((F33+G33+H33+I33+J33)/10,2)) -> 0.67 | F33: =IF(COUNT(K33:AG33)=0,"",(K33*10+L33*8+M33*7+N33*5)/3) -> 0 | G33: =IF(COUNT(K33:AG33)=0,"",(P33*8+Q33*7+R33*5+S33*5)/3) -> 0 | H33: =IF(COUNT(K33:AG33)=0,"",(U33*6+V33*6+W33*4+X33*3+Y33*3+Z33*3)/3) -> 0 | I33: =IF(COUNT(K33:AG33)=0,"",AB33*3+AC33*2+AD33*2+AE33*1) -> 0 | J33: =IF(COUNT(K33:AG33)=0,"",(AF33*5+AG33*5)/3) -> 6.6666667 | AF33: 2 | AG33: 2 | AI33: Acho q da pra passar, foi bem até
B34: e278588@dac.unicamp.br | C34: Enrico Tristão e Mello de Oliveira | D34: Ferro | E34: =IF(COUNT(K34:AG34)=0,"",ROUND((F34+G34+H34+I34+J34)/10,2)) -> 0.5 | F34: =IF(COUNT(K34:AG34)=0,"",(K34*10+L34*8+M34*7+N34*5)/3) -> 0 | G34: =IF(COUNT(K34:AG34)=0,"",(P34*8+Q34*7+R34*5+S34*5)/3) -> 0 | H34: =IF(COUNT(K34:AG34)=0,"",(U34*6+V34*6+W34*4+X34*3+Y34*3+Z34*3)/3) -> 0 | I34: =IF(COUNT(K34:AG34)=0,"",AB34*3+AC34*2+AD34*2+AE34*1) -> 0 | J34: =IF(COUNT(K34:AG34)=0,"",(AF34*5+AG34*5)/3) -> 5 | AF34: 2 | AG34: 1 | AI34: Achei q falou bem até, mas n acho q falou pq quer entrar no CCU
B35: e221509@dac.unicamp.br | C35: Eduardo Alves Henrique | D35: Proc | E35: =IF(COUNT(K35:AG35)=0,"",ROUND((F35+G35+H35+I35+J35)/10,2)) -> 0.5 | F35: =IF(COUNT(K35:AG35)=0,"",(K35*10+L35*8+M35*7+N35*5)/3) -> 0 | G35: =IF(COUNT(K35:AG35)=0,"",(P35*8+Q35*7+R35*5+S35*5)/3) -> 0 | H35: =IF(COUNT(K35:AG35)=0,"",(U35*6+V35*6+W35*4+X35*3+Y35*3+Z35*3)/3) -> 0 | I35: =IF(COUNT(K35:AG35)=0,"",AB35*3+AC35*2+AD35*2+AE35*1) -> 0 | J35: =IF(COUNT(K35:AG35)=0,"",(AF35*5+AG35*5)/3) -> 5 | AF35: 2 | AG35: 1 | AI35: 80% no GMAT. Ao mesmo tempo fala que pode não se interessar pelo CCU, como pode se tornar liderança (???).
B36: l304532@dac.unicamp.br | C36: Leandra Cunha de Souza | D36: Proc | E36: =IF(COUNT(K36:AG36)=0,"",ROUND((F36+G36+H36+I36+J36)/10,2)) -> 0.67 | F36: =IF(COUNT(K36:AG36)=0,"",(K36*10+L36*8+M36*7+N36*5)/3) -> 0 | G36: =IF(COUNT(K36:AG36)=0,"",(P36*8+Q36*7+R36*5+S36*5)/3) -> 0 | H36: =IF(COUNT(K36:AG36)=0,"",(U36*6+V36*6+W36*4+X36*3+Y36*3+Z36*3)/3) -> 0 | I36: =IF(COUNT(K36:AG36)=0,"",AB36*3+AC36*2+AD36*2+AE36*1) -> 0 | J36: =IF(COUNT(K36:AG36)=0,"",(AF36*5+AG36*5)/3) -> 6.6666667 | AF36: 2 | AG36: 2 | AI36: GMAT inconclusivo se ela colou. Nada de especial.
B37: v188630@dac.unicamp.br | C37: Vagner Ássimos Gomes Carlos Filho | D37: Proc | E37: =IF(COUNT(K37:AG37)=0,"",ROUND((F37+G37+H37+I37+J37)/10,2)) -> 0.67 | F37: =IF(COUNT(K37:AG37)=0,"",(K37*10+L37*8+M37*7+N37*5)/3) -> 0 | G37: =IF(COUNT(K37:AG37)=0,"",(P37*8+Q37*7+R37*5+S37*5)/3) -> 0 | H37: =IF(COUNT(K37:AG37)=0,"",(U37*6+V37*6+W37*4+X37*3+Y37*3+Z37*3)/3) -> 0 | I37: =IF(COUNT(K37:AG37)=0,"",AB37*3+AC37*2+AD37*2+AE37*1) -> 0 | J37: =IF(COUNT(K37:AG37)=0,"",(AF37*5+AG37*5)/3) -> 6.6666667 | AF37: 3 | AG37: 1 | AI37: Mais de 80% no GMAT. Falou quer CCU e ia nas palestras mas NÃO falou sobre ele, haviam mais 30s para falar.
B38: m277865@dac.unicamp.br | C38: Mariana Nunes Galvão Sant'Anna | D38: Proc | E38: =IF(COUNT(K38:AG38)=0,"",ROUND((F38+G38+H38+I38+J38)/10,2)) -> 0.83 | F38: =IF(COUNT(K38:AG38)=0,"",(K38*10+L38*8+M38*7+N38*5)/3) -> 0 | G38: =IF(COUNT(K38:AG38)=0,"",(P38*8+Q38*7+R38*5+S38*5)/3) -> 0 | H38: =IF(COUNT(K38:AG38)=0,"",(U38*6+V38*6+W38*4+X38*3+Y38*3+Z38*3)/3) -> 0 | I38: =IF(COUNT(K38:AG38)=0,"",AB38*3+AC38*2+AD38*2+AE38*1) -> 0 | J38: =IF(COUNT(K38:AG38)=0,"",(AF38*5+AG38*5)/3) -> 8.3333333 | AF38: 2 | AG38: 3 | AI38: Foi bem no GMAT. Falou muito rápido, mas trouxe ótima história. Se mostrou engajada.
B39: a266739@dac.unicamp.br | C39: Aslan Rodrigues Maia | D39: Proc | E39: =IF(COUNT(K39:AG39)=0,"",ROUND((F39+G39+H39+I39+J39)/10,2)) -> 0.83 | F39: =IF(COUNT(K39:AG39)=0,"",(K39*10+L39*8+M39*7+N39*5)/3) -> 0 | G39: =IF(COUNT(K39:AG39)=0,"",(P39*8+Q39*7+R39*5+S39*5)/3) -> 0 | H39: =IF(COUNT(K39:AG39)=0,"",(U39*6+V39*6+W39*4+X39*3+Y39*3+Z39*3)/3) -> 0 | I39: =IF(COUNT(K39:AG39)=0,"",AB39*3+AC39*2+AD39*2+AE39*1) -> 0 | J39: =IF(COUNT(K39:AG39)=0,"",(AF39*5+AG39*5)/3) -> 8.3333333 | AF39: 2 | AG39: 3 | AI39: quase 70% do GMAT. Vídeo parece que lia um teleprompter, mas fala bem.
B40: j278641@dac.unicamp.br | C40: João Gabriel de Oliveira Morcelli | D40: victor | E40: =IF(COUNT(K40:AG40)=0,"",ROUND((F40+G40+H40+I40+J40)/10,2)) -> 0.67 | F40: =IF(COUNT(K40:AG40)=0,"",(K40*10+L40*8+M40*7+N40*5)/3) -> 0 | G40: =IF(COUNT(K40:AG40)=0,"",(P40*8+Q40*7+R40*5+S40*5)/3) -> 0 | H40: =IF(COUNT(K40:AG40)=0,"",(U40*6+V40*6+W40*4+X40*3+Y40*3+Z40*3)/3) -> 0 | I40: =IF(COUNT(K40:AG40)=0,"",AB40*3+AC40*2+AD40*2+AE40*1) -> 0 | J40: =IF(COUNT(K40:AG40)=0,"",(AF40*5+AG40*5)/3) -> 6.6666667 | AF40: 2 | AG40: 2 | AI40: motivos bons mas não falou do clube, tinha roteiro claramente no vídeo
B41: r278709@dac.unicamp.br | C41: Raphael Negrini Saggioro | D41: victor | E41: =IF(COUNT(K41:AG41)=0,"",ROUND((F41+G41+H41+I41+J41)/10,2)) -> 0.83 | F41: =IF(COUNT(K41:AG41)=0,"",(K41*10+L41*8+M41*7+N41*5)/3) -> 0 | G41: =IF(COUNT(K41:AG41)=0,"",(P41*8+Q41*7+R41*5+S41*5)/3) -> 0 | H41: =IF(COUNT(K41:AG41)=0,"",(U41*6+V41*6+W41*4+X41*3+Y41*3+Z41*3)/3) -> 0 | I41: =IF(COUNT(K41:AG41)=0,"",AB41*3+AC41*2+AD41*2+AE41*1) -> 0 | J41: =IF(COUNT(K41:AG41)=0,"",(AF41*5+AG41*5)/3) -> 8.3333333 | AF41: 3 | AG41: 2 | AI41: N respondeu diretamente a segunda pergunta mas meio q falou pq era bom e falou de todos os projetos, leu sobre
B42: g278107@dac.unicamp.br | C42: Gustavo Daher Pereira | D42: victor | E42: =IF(COUNT(K42:AG42)=0,"",ROUND((F42+G42+H42+I42+J42)/10,2)) -> 0.67 | F42: =IF(COUNT(K42:AG42)=0,"",(K42*10+L42*8+M42*7+N42*5)/3) -> 0 | G42: =IF(COUNT(K42:AG42)=0,"",(P42*8+Q42*7+R42*5+S42*5)/3) -> 0 | H42: =IF(COUNT(K42:AG42)=0,"",(U42*6+V42*6+W42*4+X42*3+Y42*3+Z42*3)/3) -> 0 | I42: =IF(COUNT(K42:AG42)=0,"",AB42*3+AC42*2+AD42*2+AE42*1) -> 0 | J42: =IF(COUNT(K42:AG42)=0,"",(AF42*5+AG42*5)/3) -> 6.6666667 | AF42: 2 | AG42: 2 | AI42: Falou de palestras, achei prolixo e video demorado
... B49: i253464@dac.unicamp.br | C49: Isadora Kluge Dorigan | D49: Fred | E49: =IF(COUNT(K49:AG49)=0,"",ROUND((F49+G49+H49+I49+J49)/10,2)) -> 1 | F49: =IF(COUNT(K49:AG49)=0,"",(K49*10+L49*8+M49*7+N49*5)/3) -> 0 | G49: =IF(COUNT(K49:AG49)=0,"",(P49*8+Q49*7+R49*5+S49*5)/3) -> 0 | H49: =IF(COUNT(K49:AG49)=0,"",(U49*6+V49*6+W49*4+X49*3+Y49*3+Z49*3)/3) -> 0 | I49: =IF(COUNT(K49:AG49)=0,"",AB49*3+AC49*2+AD49*2+AE49*1) -> 0 | J49: =IF(COUNT(K49:AG49)=0,"",(AF49*5+AG49*5)/3) -> 10 | AF49: 3 | AG49: 3 | AI49: Mandou bem no vídeo e vai ser a próxima ana bia + verena
E50: =IF(COUNT(K50:AG50)=0,"",ROUND((F50+G50+H50+I50+J50)/10,2)) | F50: =IF(COUNT(K50:AG50)=0,"",(K50*10+L50*8+M50*7+N50*5)/3) | G50: =IF(COUNT(K50:AG50)=0,"",(P50*8+Q50*7+R50*5+S50*5)/3) | H50: =IF(COUNT(K50:AG50)=0,"",(U50*6+V50*6+W50*4+X50*3+Y50*3+Z50*3)/3) | I50: =IF(COUNT(K50:AG50)=0,"",AB50*3+AC50*2+AD50*2+AE50*1) | J50: =IF(COUNT(K50:AG50)=0,"",(AF50*5+AG50*5)/3)
E51: =IF(COUNT(K51:AG51)=0,"",ROUND((F51+G51+H51+I51+J51)/10,2)) | F51: =IF(COUNT(K51:AG51)=0,"",(K51*10+L51*8+M51*7+N51*5)/3) | G51: =IF(COUNT(K51:AG51)=0,"",(P51*8+Q51*7+R51*5+S51*5)/3) | H51: =IF(COUNT(K51:AG51)=0,"",(U51*6+V51*6+W51*4+X51*3+Y51*3+Z51*3)/3) | I51: =IF(COUNT(K51:AG51)=0,"",AB51*3+AC51*2+AD51*2+AE51*1) | J51: =IF(COUNT(K51:AG51)=0,"",(AF51*5+AG51*5)/3)
E52: =IF(COUNT(K52:AG52)=0,"",ROUND((F52+G52+H52+I52+J52)/10,2)) | F52: =IF(COUNT(K52:AG52)=0,"",(K52*10+L52*8+M52*7+N52*5)/3) | G52: =IF(COUNT(K52:AG52)=0,"",(P52*8+Q52*7+R52*5+S52*5)/3) | H52: =IF(COUNT(K52:AG52)=0,"",(U52*6+V52*6+W52*4+X52*3+Y52*3+Z52*3)/3) | I52: =IF(COUNT(K52:AG52)=0,"",AB52*3+AC52*2+AD52*2+AE52*1) | J52: =IF(COUNT(K52:AG52)=0,"",(AF52*5+AG52*5)/3)
E53: =IF(COUNT(K53:AG53)=0,"",ROUND((F53+G53+H53+I53+J53)/10,2)) | F53: =IF(COUNT(K53:AG53)=0,"",(K53*10+L53*8+M53*7+N53*5)/3) | G53: =IF(COUNT(K53:AG53)=0,"",(P53*8+Q53*7+R53*5+S53*5)/3) | H53: =IF(COUNT(K53:AG53)=0,"",(U53*6+V53*6+W53*4+X53*3+Y53*3+Z53*3)/3) | I53: =IF(COUNT(K53:AG53)=0,"",AB53*3+AC53*2+AD53*2+AE53*1) | J53: =IF(COUNT(K53:AG53)=0,"",(AF53*5+AG53*5)/3)
E54: =IF(COUNT(K54:AG54)=0,"",ROUND((F54+G54+H54+I54+J54)/10,2)) | F54: =IF(COUNT(K54:AG54)=0,"",(K54*10+L54*8+M54*7+N54*5)/3) | G54: =IF(COUNT(K54:AG54)=0,"",(P54*8+Q54*7+R54*5+S54*5)/3) | H54: =IF(COUNT(K54:AG54)=0,"",(U54*6+V54*6+W54*4+X54*3+Y54*3+Z54*3)/3) | I54: =IF(COUNT(K54:AG54)=0,"",AB54*3+AC54*2+AD54*2+AE54*1) | J54: =IF(COUNT(K54:AG54)=0,"",(AF54*5+AG54*5)/3)
E55: =IF(COUNT(K55:AG55)=0,"",ROUND((F55+G55+H55+I55+J55)/10,2)) | F55: =IF(COUNT(K55:AG55)=0,"",(K55*10+L55*8+M55*7+N55*5)/3) | G55: =IF(COUNT(K55:AG55)=0,"",(P55*8+Q55*7+R55*5+S55*5)/3) | H55: =IF(COUNT(K55:AG55)=0,"",(U55*6+V55*6+W55*4+X55*3+Y55*3+Z55*3)/3) | I55: =IF(COUNT(K55:AG55)=0,"",AB55*3+AC55*2+AD55*2+AE55*1) | J55: =IF(COUNT(K55:AG55)=0,"",(AF55*5+AG55*5)/3)
E56: =IF(COUNT(K56:AG56)=0,"",ROUND((F56+G56+H56+I56+J56)/10,2)) | F56: =IF(COUNT(K56:AG56)=0,"",(K56*10+L56*8+M56*7+N56*5)/3) | G56: =IF(COUNT(K56:AG56)=0,"",(P56*8+Q56*7+R56*5+S56*5)/3) | H56: =IF(COUNT(K56:AG56)=0,"",(U56*6+V56*6+W56*4+X56*3+Y56*3+Z56*3)/3) | I56: =IF(COUNT(K56:AG56)=0,"",AB56*3+AC56*2+AD56*2+AE56*1) | J56: =IF(COUNT(K56:AG56)=0,"",(AF56*5+AG56*5)/3)
...

Sheet Consolidado
B2: CONSOLIDADO — cole os nomes na coluna B; o resto se calcula sozinho.
B3: =IF(COUNTA($B$5:$B$64)=0,"Cole os nomes dos candidatos na coluna B para começar.","Avaliações completas: "&COUNTIF($D$5:$D$64,">=2")&" de "&COUNTA($B$5:$B$64)&" candidatos ("&TEXT(COUNTIF($D$5:$D$64,">=2")/COUNTA($B$5:$B$64),"0%")&") • Ainda com 1 avaliador só: "&COUNTIF($D$5:$D$64,1)&" • Sem nenhuma nota: "&COUNTIF($D$5:$D$64,0)) -> Avaliações completas: 0 de 21 candidatos (0%) • Ainda com 1 avaliador só: 0 • Sem nenhuma nota: 21
A4: # | B4: Candidato(a) | C4: Nome | D4: Nº aval. | E4: NOTA FINAL | F4: Nota aval. 1 | G4: Nota aval. 2 | H4: Diverg. | I4: Alerta | J4: Flag | K4: Horas/sem | L4: Motivo da flag / o que perguntar na entrevista | M4: Ranking | N4: Entrevista: refez a conta? | O4: Decisão final
A5: =IF($B5="","",ROW()-4) -> 1 | B5: g278083@dac.unicamp.br | C5: Gabrielle Cristofani do Rosario | D5: =IF($B5="","",COUNTIFS('Avaliação'!$C$7:$C$206,$B5,'Avaliação'!$E$7:$E$206,">=0")) -> 0 | E5: =IF($B5="","",IFERROR(ROUND(AVERAGEIF('Avaliação'!$C$7:$C$206,$B5,'Avaliação'!$E$7:$E$206),2),"")) | F5: {=IF($B5="","",IFERROR(INDEX('Avaliação'!$E$7:$E$206,MATCH($B5,'Avaliação'!$C$7:$C$206,0)),""))} | G5: =IF($B5="","",IF($D5<>2,"",IF($F5="","",ROUND(SUMIF('Avaliação'!$C$7:$C$206,$B5,'Avaliação'!$E$7:$E$206)-$F5,2)))) | H5: =IF($B5="","",IF(OR($F5="",$G5=""),"",ROUND(ABS($F5-$G5),2))) | I5: =IF($B5="","",IF($D5<2,"⚠ falta 2º avaliador",IF($D5>2,"⚠ mais de 2 avaliações — conferir",IF(AND(ISNUMBER($H5),$H5>1),"⚠ divergência > 1,0 — média suspensa, calibrar","OK")))) -> ⚠ falta 2º avaliador | M5: =IF($E5="","",COUNTIF($E$5:$E$64,">"&$E5)+1) | N5: =IF($B5="","",IF(Entrevista!$H5="","",Entrevista!$H5)) | O5: =IF($B5="","",IF(Entrevista!$L5="","",Entrevista!$L5))
A6: =IF($B6="","",ROW()-4) -> 2 | B6: b309603@dac.unicamp.br | C6: Bruno Heberth Oliveira Bastos | D6: =IF($B6="","",COUNTIFS('Avaliação'!$C$7:$C$206,$B6,'Avaliação'!$E$7:$E$206,">=0")) -> 0 | E6: =IF($B6="","",IFERROR(ROUND(AVERAGEIF('Avaliação'!$C$7:$C$206,$B6,'Avaliação'!$E$7:$E$206),2),"")) | F6: {=IF($B6="","",IFERROR(INDEX('Avaliação'!$E$7:$E$206,MATCH($B6,'Avaliação'!$C$7:$C$206,0)),""))} | G6: =IF($B6="","",IF($D6<>2,"",IF($F6="","",ROUND(SUMIF('Avaliação'!$C$7:$C$206,$B6,'Avaliação'!$E$7:$E$206)-$F6,2)))) | H6: =IF($B6="","",IF(OR($F6="",$G6=""),"",ROUND(ABS($F6-$G6),2))) | I6: =IF($B6="","",IF($D6<2,"⚠ falta 2º avaliador",IF($D6>2,"⚠ mais de 2 avaliações — conferir",IF(AND(ISNUMBER($H6),$H6>1),"⚠ divergência > 1,0 — média suspensa, calibrar","OK")))) -> ⚠ falta 2º avaliador | M6: =IF($E6="","",COUNTIF($E$5:$E$64,">"&$E6)+1) | N6: =IF($B6="","",IF(Entrevista!$H6="","",Entrevista!$H6)) | O6: =IF($B6="","",IF(Entrevista!$L6="","",Entrevista!$L6))
A7: =IF($B7="","",ROW()-4) -> 3 | B7: j309764@dac.unicamp.br | C7: João Pedro Mendes Stama | D7: =IF($B7="","",COUNTIFS('Avaliação'!$C$7:$C$206,$B7,'Avaliação'!$E$7:$E$206,">=0")) -> 0 | E7: =IF($B7="","",IFERROR(ROUND(AVERAGEIF('Avaliação'!$C$7:$C$206,$B7,'Avaliação'!$E$7:$E$206),2),"")) | F7: {=IF($B7="","",IFERROR(INDEX('Avaliação'!$E$7:$E$206,MATCH($B7,'Avaliação'!$C$7:$C$206,0)),""))} | G7: =IF($B7="","",IF($D7<>2,"",IF($F7="","",ROUND(SUMIF('Avaliação'!$C$7:$C$206,$B7,'Avaliação'!$E$7:$E$206)-$F7,2)))) | H7: =IF($B7="","",IF(OR($F7="",$G7=""),"",ROUND(ABS($F7-$G7),2))) | I7: =IF($B7="","",IF($D7<2,"⚠ falta 2º avaliador",IF($D7>2,"⚠ mais de 2 avaliações — conferir",IF(AND(ISNUMBER($H7),$H7>1),"⚠ divergência > 1,0 — média suspensa, calibrar","OK")))) -> ⚠ falta 2º avaliador | M7: =IF($E7="","",COUNTIF($E$5:$E$64,">"&$E7)+1) | N7: =IF($B7="","",IF(Entrevista!$H7="","",Entrevista!$H7)) | O7: =IF($B7="","",IF(Entrevista!$L7="","",Entrevista!$L7))
A8: =IF($B8="","",ROW()-4) -> 4 | B8: r238449@dac.unicamp.br | C8: Rafael Ponciano Rodrigues dos Santos | D8: =IF($B8="","",COUNTIFS('Avaliação'!$C$7:$C$206,$B8,'Avaliação'!$E$7:$E$206,">=0")) -> 0 | E8: =IF($B8="","",IFERROR(ROUND(AVERAGEIF('Avaliação'!$C$7:$C$206,$B8,'Avaliação'!$E$7:$E$206),2),"")) | F8: {=IF($B8="","",IFERROR(INDEX('Avaliação'!$E$7:$E$206,MATCH($B8,'Avaliação'!$C$7:$C$206,0)),""))} | G8: =IF($B8="","",IF($D8<>2,"",IF($F8="","",ROUND(SUMIF('Avaliação'!$C$7:$C$206,$B8,'Avaliação'!$E$7:$E$206)-$F8,2)))) | H8: =IF($B8="","",IF(OR($F8="",$G8=""),"",ROUND(ABS($F8-$G8),2))) | I8: =IF($B8="","",IF($D8<2,"⚠ falta 2º avaliador",IF($D8>2,"⚠ mais de 2 avaliações — conferir",IF(AND(ISNUMBER($H8),$H8>1),"⚠ divergência > 1,0 — média suspensa, calibrar","OK")))) -> ⚠ falta 2º avaliador | M8: =IF($E8="","",COUNTIF($E$5:$E$64,">"&$E8)+1) | N8: =IF($B8="","",IF(Entrevista!$H8="","",Entrevista!$H8)) | O8: =IF($B8="","",IF(Entrevista!$L8="","",Entrevista!$L8))
A9: =IF($B9="","",ROW()-4) -> 5 | B9: enzo.gag17@gmail.com | C9: Enzo Chofakian Gagliardi | D9: =IF($B9="","",COUNTIFS('Avaliação'!$C$7:$C$206,$B9,'Avaliação'!$E$7:$E$206,">=0")) -> 0 | E9: =IF($B9="","",IFERROR(ROUND(AVERAGEIF('Avaliação'!$C$7:$C$206,$B9,'Avaliação'!$E$7:$E$206),2),"")) | F9: {=IF($B9="","",IFERROR(INDEX('Avaliação'!$E$7:$E$206,MATCH($B9,'Avaliação'!$C$7:$C$206,0)),""))} | G9: =IF($B9="","",IF($D9<>2,"",IF($F9="","",ROUND(SUMIF('Avaliação'!$C$7:$C$206,$B9,'Avaliação'!$E$7:$E$206)-$F9,2)))) | H9: =IF($B9="","",IF(OR($F9="",$G9=""),"",ROUND(ABS($F9-$G9),2))) | I9: =IF($B9="","",IF($D9<2,"⚠ falta 2º avaliador",IF($D9>2,"⚠ mais de 2 avaliações — conferir",IF(AND(ISNUMBER($H9),$H9>1),"⚠ divergência > 1,0 — média suspensa, calibrar","OK")))) -> ⚠ falta 2º avaliador | M9: =IF($E9="","",COUNTIF($E$5:$E$64,">"&$E9)+1) | N9: =IF($B9="","",IF(Entrevista!$H9="","",Entrevista!$H9)) | O9: =IF($B9="","",IF(Entrevista!$L9="","",Entrevista!$L9))
A10: =IF($B10="","",ROW()-4) -> 6 | B10: e278588@dac.unicamp.br | C10: Enrico Tristão e Mello de Oliveira | D10: =IF($B10="","",COUNTIFS('Avaliação'!$C$7:$C$206,$B10,'Avaliação'!$E$7:$E$206,">=0")) -> 0 | E10: =IF($B10="","",IFERROR(ROUND(AVERAGEIF('Avaliação'!$C$7:$C$206,$B10,'Avaliação'!$E$7:$E$206),2),"")) | F10: {=IF($B10="","",IFERROR(INDEX('Avaliação'!$E$7:$E$206,MATCH($B10,'Avaliação'!$C$7:$C$206,0)),""))} | G10: =IF($B10="","",IF($D10<>2,"",IF($F10="","",ROUND(SUMIF('Avaliação'!$C$7:$C$206,$B10,'Avaliação'!$E$7:$E$206)-$F10,2)))) | H10: =IF($B10="","",IF(OR($F10="",$G10=""),"",ROUND(ABS($F10-$G10),2))) | I10: =IF($B10="","",IF($D10<2,"⚠ falta 2º avaliador",IF($D10>2,"⚠ mais de 2 avaliações — conferir",IF(AND(ISNUMBER($H10),$H10>1),"⚠ divergência > 1,0 — média suspensa, calibrar","OK")))) -> ⚠ falta 2º avaliador | M10: =IF($E10="","",COUNTIF($E$5:$E$64,">"&$E10)+1) | N10: =IF($B10="","",IF(Entrevista!$H10="","",Entrevista!$H10)) | O10: =IF($B10="","",IF(Entrevista!$L10="","",Entrevista!$L10))
A11: =IF($B11="","",ROW()-4) -> 7 | B11: e221509@dac.unicamp.br | C11: Eduardo Alves Henrique | D11: =IF($B11="","",COUNTIFS('Avaliação'!$C$7:$C$206,$B11,'Avaliação'!$E$7:$E$206,">=0")) -> 0 | E11: =IF($B11="","",IFERROR(ROUND(AVERAGEIF('Avaliação'!$C$7:$C$206,$B11,'Avaliação'!$E$7:$E$206),2),"")) | F11: {=IF($B11="","",IFERROR(INDEX('Avaliação'!$E$7:$E$206,MATCH($B11,'Avaliação'!$C$7:$C$206,0)),""))} | G11: =IF($B11="","",IF($D11<>2,"",IF($F11="","",ROUND(SUMIF('Avaliação'!$C$7:$C$206,$B11,'Avaliação'!$E$7:$E$206)-$F11,2)))) | H11: =IF($B11="","",IF(OR($F11="",$G11=""),"",ROUND(ABS($F11-$G11),2))) | I11: =IF($B11="","",IF($D11<2,"⚠ falta 2º avaliador",IF($D11>2,"⚠ mais de 2 avaliações — conferir",IF(AND(ISNUMBER($H11),$H11>1),"⚠ divergência > 1,0 — média suspensa, calibrar","OK")))) -> ⚠ falta 2º avaliador | M11: =IF($E11="","",COUNTIF($E$5:$E$64,">"&$E11)+1) | N11: =IF($B11="","",IF(Entrevista!$H11="","",Entrevista!$H11)) | O11: =IF($B11="","",IF(Entrevista!$L11="","",Entrevista!$L11))
A12: =IF($B12="","",ROW()-4) -> 8 | B12: l304532@dac.unicamp.br | C12: Leandra Cunha de Souza | D12: =IF($B12="","",COUNTIFS('Avaliação'!$C$7:$C$206,$B12,'Avaliação'!$E$7:$E$206,">=0")) -> 0 | E12: =IF($B12="","",IFERROR(ROUND(AVERAGEIF('Avaliação'!$C$7:$C$206,$B12,'Avaliação'!$E$7:$E$206),2),"")) | F12: {=IF($B12="","",IFERROR(INDEX('Avaliação'!$E$7:$E$206,MATCH($B12,'Avaliação'!$C$7:$C$206,0)),""))} | G12: =IF($B12="","",IF($D12<>2,"",IF($F12="","",ROUND(SUMIF('Avaliação'!$C$7:$C$206,$B12,'Avaliação'!$E$7:$E$206)-$F12,2)))) | H12: =IF($B12="","",IF(OR($F12="",$G12=""),"",ROUND(ABS($F12-$G12),2))) | I12: =IF($B12="","",IF($D12<2,"⚠ falta 2º avaliador",IF($D12>2,"⚠ mais de 2 avaliações — conferir",IF(AND(ISNUMBER($H12),$H12>1),"⚠ divergência > 1,0 — média suspensa, calibrar","OK")))) -> ⚠ falta 2º avaliador | M12: =IF($E12="","",COUNTIF($E$5:$E$64,">"&$E12)+1) | N12: =IF($B12="","",IF(Entrevista!$H12="","",Entrevista!$H12)) | O12: =IF($B12="","",IF(Entrevista!$L12="","",Entrevista!$L12))
A13: =IF($B13="","",ROW()-4) -> 9 | B13: v188630@dac.unicamp.br | C13: Vagner Ássimos Gomes Carlos Filho | D13: =IF($B13="","",COUNTIFS('Avaliação'!$C$7:$C$206,$B13,'Avaliação'!$E$7:$E$206,">=0")) -> 0 | E13: =IF($B13="","",IFERROR(ROUND(AVERAGEIF('Avaliação'!$C$7:$C$206,$B13,'Avaliação'!$E$7:$E$206),2),"")) | F13: {=IF($B13="","",IFERROR(INDEX('Avaliação'!$E$7:$E$206,MATCH($B13,'Avaliação'!$C$7:$C$206,0)),""))} | G13: =IF($B13="","",IF($D13<>2,"",IF($F13="","",ROUND(SUMIF('Avaliação'!$C$7:$C$206,$B13,'Avaliação'!$E$7:$E$206)-$F13,2)))) | H13: =IF($B13="","",IF(OR($F13="",$G13=""),"",ROUND(ABS($F13-$G13),2))) | I13: =IF($B13="","",IF($D13<2,"⚠ falta 2º avaliador",IF($D13>2,"⚠ mais de 2 avaliações — conferir",IF(AND(ISNUMBER($H13),$H13>1),"⚠ divergência > 1,0 — média suspensa, calibrar","OK")))) -> ⚠ falta 2º avaliador | M13: =IF($E13="","",COUNTIF($E$5:$E$64,">"&$E13)+1) | N13: =IF($B13="","",IF(Entrevista!$H13="","",Entrevista!$H13)) | O13: =IF($B13="","",IF(Entrevista!$L13="","",Entrevista!$L13))
A14: =IF($B14="","",ROW()-4) -> 10 | B14: m277865@dac.unicamp.br | C14: Mariana Nunes Galvão Sant'Anna | D14: =IF($B14="","",COUNTIFS('Avaliação'!$C$7:$C$206,$B14,'Avaliação'!$E$7:$E$206,">=0")) -> 0 | E14: =IF($B14="","",IFERROR(ROUND(AVERAGEIF('Avaliação'!$C$7:$C$206,$B14,'Avaliação'!$E$7:$E$206),2),"")) | F14: {=IF($B14="","",IFERROR(INDEX('Avaliação'!$E$7:$E$206,MATCH($B14,'Avaliação'!$C$7:$C$206,0)),""))} | G14: =IF($B14="","",IF($D14<>2,"",IF($F14="","",ROUND(SUMIF('Avaliação'!$C$7:$C$206,$B14,'Avaliação'!$E$7:$E$206)-$F14,2)))) | H14: =IF($B14="","",IF(OR($F14="",$G14=""),"",ROUND(ABS($F14-$G14),2))) | I14: =IF($B14="","",IF($D14<2,"⚠ falta 2º avaliador",IF($D14>2,"⚠ mais de 2 avaliações — conferir",IF(AND(ISNUMBER($H14),$H14>1),"⚠ divergência > 1,0 — média suspensa, calibrar","OK")))) -> ⚠ falta 2º avaliador | M14: =IF($E14="","",COUNTIF($E$5:$E$64,">"&$E14)+1) | N14: =IF($B14="","",IF(Entrevista!$H14="","",Entrevista!$H14)) | O14: =IF($B14="","",IF(Entrevista!$L14="","",Entrevista!$L14))
A15: =IF($B15="","",ROW()-4) -> 11 | B15: a266739@dac.unicamp.br | C15: Aslan Rodrigues Maia | D15: =IF($B15="","",COUNTIFS('Avaliação'!$C$7:$C$206,$B15,'Avaliação'!$E$7:$E$206,">=0")) -> 0 | E15: =IF($B15="","",IFERROR(ROUND(AVERAGEIF('Avaliação'!$C$7:$C$206,$B15,'Avaliação'!$E$7:$E$206),2),"")) | F15: {=IF($B15="","",IFERROR(INDEX('Avaliação'!$E$7:$E$206,MATCH($B15,'Avaliação'!$C$7:$C$206,0)),""))} | G15: =IF($B15="","",IF($D15<>2,"",IF($F15="","",ROUND(SUMIF('Avaliação'!$C$7:$C$206,$B15,'Avaliação'!$E$7:$E$206)-$F15,2)))) | H15: =IF($B15="","",IF(OR($F15="",$G15=""),"",ROUND(ABS($F15-$G15),2))) | I15: =IF($B15="","",IF($D15<2,"⚠ falta 2º avaliador",IF($D15>2,"⚠ mais de 2 avaliações — conferir",IF(AND(ISNUMBER($H15),$H15>1),"⚠ divergência > 1,0 — média suspensa, calibrar","OK")))) -> ⚠ falta 2º avaliador | M15: =IF($E15="","",COUNTIF($E$5:$E$64,">"&$E15)+1) | N15: =IF($B15="","",IF(Entrevista!$H15="","",Entrevista!$H15)) | O15: =IF($B15="","",IF(Entrevista!$L15="","",Entrevista!$L15))
A16: =IF($B16="","",ROW()-4) -> 12 | B16: j278641@dac.unicamp.br | C16: João Gabriel de Oliveira Morcelli | D16: =IF($B16="","",COUNTIFS('Avaliação'!$C$7:$C$206,$B16,'Avaliação'!$E$7:$E$206,">=0")) -> 0 | E16: =IF($B16="","",IFERROR(ROUND(AVERAGEIF('Avaliação'!$C$7:$C$206,$B16,'Avaliação'!$E$7:$E$206),2),"")) | F16: {=IF($B16="","",IFERROR(INDEX('Avaliação'!$E$7:$E$206,MATCH($B16,'Avaliação'!$C$7:$C$206,0)),""))} | G16: =IF($B16="","",IF($D16<>2,"",IF($F16="","",ROUND(SUMIF('Avaliação'!$C$7:$C$206,$B16,'Avaliação'!$E$7:$E$206)-$F16,2)))) | H16: =IF($B16="","",IF(OR($F16="",$G16=""),"",ROUND(ABS($F16-$G16),2))) | I16: =IF($B16="","",IF($D16<2,"⚠ falta 2º avaliador",IF($D16>2,"⚠ mais de 2 avaliações — conferir",IF(AND(ISNUMBER($H16),$H16>1),"⚠ divergência > 1,0 — média suspensa, calibrar","OK")))) -> ⚠ falta 2º avaliador | M16: =IF($E16="","",COUNTIF($E$5:$E$64,">"&$E16)+1) | N16: =IF($B16="","",IF(Entrevista!$H16="","",Entrevista!$H16)) | O16: =IF($B16="","",IF(Entrevista!$L16="","",Entrevista!$L16))
... A25: =IF($B25="","",ROW()-4) -> 21 | B25: i253464@dac.unicamp.br | C25: Isadora Kluge Dorigan | D25: =IF($B25="","",COUNTIFS('Avaliação'!$C$7:$C$206,$B25,'Avaliação'!$E$7:$E$206,">=0")) -> 0 | E25: =IF($B25="","",IFERROR(ROUND(AVERAGEIF('Avaliação'!$C$7:$C$206,$B25,'Avaliação'!$E$7:$E$206),2),"")) | F25: {=IF($B25="","",IFERROR(INDEX('Avaliação'!$E$7:$E$206,MATCH($B25,'Avaliação'!$C$7:$C$206,0)),""))} | G25: =IF($B25="","",IF($D25<>2,"",IF($F25="","",ROUND(SUMIF('Avaliação'!$C$7:$C$206,$B25,'Avaliação'!$E$7:$E$206)-$F25,2)))) | H25: =IF($B25="","",IF(OR($F25="",$G25=""),"",ROUND(ABS($F25-$G25),2))) | I25: =IF($B25="","",IF($D25<2,"⚠ falta 2º avaliador",IF($D25>2,"⚠ mais de 2 avaliações — conferir",IF(AND(ISNUMBER($H25),$H25>1),"⚠ divergência > 1,0 — média suspensa, calibrar","OK")))) -> ⚠ falta 2º avaliador | M25: =IF($E25="","",COUNTIF($E$5:$E$64,">"&$E25)+1) | N25: =IF($B25="","",IF(Entrevista!$H25="","",Entrevista!$H25)) | O25: =IF($B25="","",IF(Entrevista!$L25="","",Entrevista!$L25))
A26: =IF($B26="","",ROW()-4) | D26: =IF($B26="","",COUNTIFS('Avaliação'!$C$7:$C$206,$B26,'Avaliação'!$E$7:$E$206,">=0")) | E26: =IF($B26="","",IFERROR(ROUND(AVERAGEIF('Avaliação'!$C$7:$C$206,$B26,'Avaliação'!$E$7:$E$206),2),"")) | F26: {=IF($B26="","",IFERROR(INDEX('Avaliação'!$E$7:$E$206,MATCH($B26,'Avaliação'!$C$7:$C$206,0)),""))} | G26: =IF($B26="","",IF($D26<>2,"",IF($F26="","",ROUND(SUMIF('Avaliação'!$C$7:$C$206,$B26,'Avaliação'!$E$7:$E$206)-$F26,2)))) | H26: =IF($B26="","",IF(OR($F26="",$G26=""),"",ROUND(ABS($F26-$G26),2))) | I26: =IF($B26="","",IF($D26<2,"⚠ falta 2º avaliador",IF($D26>2,"⚠ mais de 2 avaliações — conferir",IF(AND(ISNUMBER($H26),$H26>1),"⚠ divergência > 1,0 — média suspensa, calibrar","OK")))) | M26: =IF($E26="","",COUNTIF($E$5:$E$64,">"&$E26)+1) | N26: =IF($B26="","",IF(Entrevista!$H26="","",Entrevista!$H26)) | O26: =IF($B26="","",IF(Entrevista!$L26="","",Entrevista!$L26))
A27: =IF($B27="","",ROW()-4) | D27: =IF($B27="","",COUNTIFS('Avaliação'!$C$7:$C$206,$B27,'Avaliação'!$E$7:$E$206,">=0")) | E27: =IF($B27="","",IFERROR(ROUND(AVERAGEIF('Avaliação'!$C$7:$C$206,$B27,'Avaliação'!$E$7:$E$206),2),"")) | F27: {=IF($B27="","",IFERROR(INDEX('Avaliação'!$E$7:$E$206,MATCH($B27,'Avaliação'!$C$7:$C$206,0)),""))} | G27: =IF($B27="","",IF($D27<>2,"",IF($F27="","",ROUND(SUMIF('Avaliação'!$C$7:$C$206,$B27,'Avaliação'!$E$7:$E$206)-$F27,2)))) | H27: =IF($B27="","",IF(OR($F27="",$G27=""),"",ROUND(ABS($F27-$G27),2))) | I27: =IF($B27="","",IF($D27<2,"⚠ falta 2º avaliador",IF($D27>2,"⚠ mais de 2 avaliações — conferir",IF(AND(ISNUMBER($H27),$H27>1),"⚠ divergência > 1,0 — média suspensa, calibrar","OK")))) | M27: =IF($E27="","",COUNTIF($E$5:$E$64,">"&$E27)+1) | N27: =IF($B27="","",IF(Entrevista!$H27="","",Entrevista!$H27)) | O27: =IF($B27="","",IF(Entrevista!$L27="","",Entrevista!$L27))
A28: =IF($B28="","",ROW()-4) | D28: =IF($B28="","",COUNTIFS('Avaliação'!$C$7:$C$206,$B28,'Avaliação'!$E$7:$E$206,">=0")) | E28: =IF($B28="","",IFERROR(ROUND(AVERAGEIF('Avaliação'!$C$7:$C$206,$B28,'Avaliação'!$E$7:$E$206),2),"")) | F28: {=IF($B28="","",IFERROR(INDEX('Avaliação'!$E$7:$E$206,MATCH($B28,'Avaliação'!$C$7:$C$206,0)),""))} | G28: =IF($B28="","",IF($D28<>2,"",IF($F28="","",ROUND(SUMIF('Avaliação'!$C$7:$C$206,$B28,'Avaliação'!$E$7:$E$206)-$F28,2)))) | H28: =IF($B28="","",IF(OR($F28="",$G28=""),"",ROUND(ABS($F28-$G28),2))) | I28: =IF($B28="","",IF($D28<2,"⚠ falta 2º avaliador",IF($D28>2,"⚠ mais de 2 avaliações — conferir",IF(AND(ISNUMBER($H28),$H28>1),"⚠ divergência > 1,0 — média suspensa, calibrar","OK")))) | M28: =IF($E28="","",COUNTIF($E$5:$E$64,">"&$E28)+1) | N28: =IF($B28="","",IF(Entrevista!$H28="","",Entrevista!$H28)) | O28: =IF($B28="","",IF(Entrevista!$L28="","",Entrevista!$L28))
A29: =IF($B29="","",ROW()-4) | D29: =IF($B29="","",COUNTIFS('Avaliação'!$C$7:$C$206,$B29,'Avaliação'!$E$7:$E$206,">=0")) | E29: =IF($B29="","",IFERROR(ROUND(AVERAGEIF('Avaliação'!$C$7:$C$206,$B29,'Avaliação'!$E$7:$E$206),2),"")) | F29: {=IF($B29="","",IFERROR(INDEX('Avaliação'!$E$7:$E$206,MATCH($B29,'Avaliação'!$C$7:$C$206,0)),""))} | G29: =IF($B29="","",IF($D29<>2,"",IF($F29="","",ROUND(SUMIF('Avaliação'!$C$7:$C$206,$B29,'Avaliação'!$E$7:$E$206)-$F29,2)))) | H29: =IF($B29="","",IF(OR($F29="",$G29=""),"",ROUND(ABS($F29-$G29),2))) | I29: =IF($B29="","",IF($D29<2,"⚠ falta 2º avaliador",IF($D29>2,"⚠ mais de 2 avaliações — conferir",IF(AND(ISNUMBER($H29),$H29>1),"⚠ divergência > 1,0 — média suspensa, calibrar","OK")))) | M29: =IF($E29="","",COUNTIF($E$5:$E$64,">"&$E29)+1) | N29: =IF($B29="","",IF(Entrevista!$H29="","",Entrevista!$H29)) | O29: =IF($B29="","",IF(Entrevista!$L29="","",Entrevista!$L29))
A30: =IF($B30="","",ROW()-4) | D30: =IF($B30="","",COUNTIFS('Avaliação'!$C$7:$C$206,$B30,'Avaliação'!$E$7:$E$206,">=0")) | E30: =IF($B30="","",IFERROR(ROUND(AVERAGEIF('Avaliação'!$C$7:$C$206,$B30,'Avaliação'!$E$7:$E$206),2),"")) | F30: {=IF($B30="","",IFERROR(INDEX('Avaliação'!$E$7:$E$206,MATCH($B30,'Avaliação'!$C$7:$C$206,0)),""))} | G30: =IF($B30="","",IF($D30<>2,"",IF($F30="","",ROUND(SUMIF('Avaliação'!$C$7:$C$206,$B30,'Avaliação'!$E$7:$E$206)-$F30,2)))) | H30: =IF($B30="","",IF(OR($F30="",$G30=""),"",ROUND(ABS($F30-$G30),2))) | I30: =IF($B30="","",IF($D30<2,"⚠ falta 2º avaliador",IF($D30>2,"⚠ mais de 2 avaliações — conferir",IF(AND(ISNUMBER($H30),$H30>1),"⚠ divergência > 1,0 — média suspensa, calibrar","OK")))) | M30: =IF($E30="","",COUNTIF($E$5:$E$64,">"&$E30)+1) | N30: =IF($B30="","",IF(Entrevista!$H30="","",Entrevista!$H30)) | O30: =IF($B30="","",IF(Entrevista!$L30="","",Entrevista!$L30))
A31: =IF($B31="","",ROW()-4) | D31: =IF($B31="","",COUNTIFS('Avaliação'!$C$7:$C$206,$B31,'Avaliação'!$E$7:$E$206,">=0")) | E31: =IF($B31="","",IFERROR(ROUND(AVERAGEIF('Avaliação'!$C$7:$C$206,$B31,'Avaliação'!$E$7:$E$206),2),"")) | F31: {=IF($B31="","",IFERROR(INDEX('Avaliação'!$E$7:$E$206,MATCH($B31,'Avaliação'!$C$7:$C$206,0)),""))} | G31: =IF($B31="","",IF($D31<>2,"",IF($F31="","",ROUND(SUMIF('Avaliação'!$C$7:$C$206,$B31,'Avaliação'!$E$7:$E$206)-$F31,2)))) | H31: =IF($B31="","",IF(OR($F31="",$G31=""),"",ROUND(ABS($F31-$G31),2))) | I31: =IF($B31="","",IF($D31<2,"⚠ falta 2º avaliador",IF($D31>2,"⚠ mais de 2 avaliações — conferir",IF(AND(ISNUMBER($H31),$H31>1),"⚠ divergência > 1,0 — média suspensa, calibrar","OK")))) | M31: =IF($E31="","",COUNTIF($E$5:$E$64,">"&$E31)+1) | N31: =IF($B31="","",IF(Entrevista!$H31="","",Entrevista!$H31)) | O31: =IF($B31="","",IF(Entrevista!$L31="","",Entrevista!$L31))
A32: =IF($B32="","",ROW()-4) | D32: =IF($B32="","",COUNTIFS('Avaliação'!$C$7:$C$206,$B32,'Avaliação'!$E$7:$E$206,">=0")) | E32: =IF($B32="","",IFERROR(ROUND(AVERAGEIF('Avaliação'!$C$7:$C$206,$B32,'Avaliação'!$E$7:$E$206),2),"")) | F32: {=IF($B32="","",IFERROR(INDEX('Avaliação'!$E$7:$E$206,MATCH($B32,'Avaliação'!$C$7:$C$206,0)),""))} | G32: =IF($B32="","",IF($D32<>2,"",IF($F32="","",ROUND(SUMIF('Avaliação'!$C$7:$C$206,$B32,'Avaliação'!$E$7:$E$206)-$F32,2)))) | H32: =IF($B32="","",IF(OR($F32="",$G32=""),"",ROUND(ABS($F32-$G32),2))) | I32: =IF($B32="","",IF($D32<2,"⚠ falta 2º avaliador",IF($D32>2,"⚠ mais de 2 avaliações — conferir",IF(AND(ISNUMBER($H32),$H32>1),"⚠ divergência > 1,0 — média suspensa, calibrar","OK")))) | M32: =IF($E32="","",COUNTIF($E$5:$E$64,">"&$E32)+1) | N32: =IF($B32="","",IF(Entrevista!$H32="","",Entrevista!$H32)) | O32: =IF($B32="","",IF(Entrevista!$L32="","",Entrevista!$L32))
A33: =IF($B33="","",ROW()-4) | D33: =IF($B33="","",COUNTIFS('Avaliação'!$C$7:$C$206,$B33,'Avaliação'!$E$7:$E$206,">=0")) | E33: =IF($B33="","",IFERROR(ROUND(AVERAGEIF('Avaliação'!$C$7:$C$206,$B33,'Avaliação'!$E$7:$E$206),2),"")) | F33: {=IF($B33="","",IFERROR(INDEX('Avaliação'!$E$7:$E$206,MATCH($B33,'Avaliação'!$C$7:$C$206,0)),""))} | G33: =IF($B33="","",IF($D33<>2,"",IF($F33="","",ROUND(SUMIF('Avaliação'!$C$7:$C$206,$B33,'Avaliação'!$E$7:$E$206)-$F33,2)))) | H33: =IF($B33="","",IF(OR($F33="",$G33=""),"",ROUND(ABS($F33-$G33),2))) | I33: =IF($B33="","",IF($D33<2,"⚠ falta 2º avaliador",IF($D33>2,"⚠ mais de 2 avaliações — conferir",IF(AND(ISNUMBER($H33),$H33>1),"⚠ divergência > 1,0 — média suspensa, calibrar","OK")))) | M33: =IF($E33="","",COUNTIF($E$5:$E$64,">"&$E33)+1) | N33: =IF($B33="","",IF(Entrevista!$H33="","",Entrevista!$H33)) | O33: =IF($B33="","",IF(Entrevista!$L33="","",Entrevista!$L33))
A34: =IF($B34="","",ROW()-4) | D34: =IF($B34="","",COUNTIFS('Avaliação'!$C$7:$C$206,$B34,'Avaliação'!$E$7:$E$206,">=0")) | E34: =IF($B34="","",IFERROR(ROUND(AVERAGEIF('Avaliação'!$C$7:$C$206,$B34,'Avaliação'!$E$7:$E$206),2),"")) | F34: {=IF($B34="","",IFERROR(INDEX('Avaliação'!$E$7:$E$206,MATCH($B34,'Avaliação'!$C$7:$C$206,0)),""))} | G34: =IF($B34="","",IF($D34<>2,"",IF($F34="","",ROUND(SUMIF('Avaliação'!$C$7:$C$206,$B34,'Avaliação'!$E$7:$E$206)-$F34,2)))) | H34: =IF($B34="","",IF(OR($F34="",$G34=""),"",ROUND(ABS($F34-$G34),2))) | I34: =IF($B34="","",IF($D34<2,"⚠ falta 2º avaliador",IF($D34>2,"⚠ mais de 2 avaliações — conferir",IF(AND(ISNUMBER($H34),$H34>1),"⚠ divergência > 1,0 — média suspensa, calibrar","OK")))) | M34: =IF($E34="","",COUNTIF($E$5:$E$64,">"&$E34)+1) | N34: =IF($B34="","",IF(Entrevista!$H34="","",Entrevista!$H34)) | O34: =IF($B34="","",IF(Entrevista!$L34="","",Entrevista!$L34))
A35: =IF($B35="","",ROW()-4) | D35: =IF($B35="","",COUNTIFS('Avaliação'!$C$7:$C$206,$B35,'Avaliação'!$E$7:$E$206,">=0")) | E35: =IF($B35="","",IFERROR(ROUND(AVERAGEIF('Avaliação'!$C$7:$C$206,$B35,'Avaliação'!$E$7:$E$206),2),"")) | F35: {=IF($B35="","",IFERROR(INDEX('Avaliação'!$E$7:$E$206,MATCH($B35,'Avaliação'!$C$7:$C$206,0)),""))} | G35: =IF($B35="","",IF($D35<>2,"",IF($F35="","",ROUND(SUMIF('Avaliação'!$C$7:$C$206,$B35,'Avaliação'!$E$7:$E$206)-$F35,2)))) | H35: =IF($B35="","",IF(OR($F35="",$G35=""),"",ROUND(ABS($F35-$G35),2))) | I35: =IF($B35="","",IF($D35<2,"⚠ falta 2º avaliador",IF($D35>2,"⚠ mais de 2 avaliações — conferir",IF(AND(ISNUMBER($H35),$H35>1),"⚠ divergência > 1,0 — média suspensa, calibrar","OK")))) | M35: =IF($E35="","",COUNTIF($E$5:$E$64,">"&$E35)+1) | N35: =IF($B35="","",IF(Entrevista!$H35="","",Entrevista!$H35)) | O35: =IF($B35="","",IF(Entrevista!$L35="","",Entrevista!$L35))
A36: =IF($B36="","",ROW()-4) | D36: =IF($B36="","",COUNTIFS('Avaliação'!$C$7:$C$206,$B36,'Avaliação'!$E$7:$E$206,">=0")) | E36: =IF($B36="","",IFERROR(ROUND(AVERAGEIF('Avaliação'!$C$7:$C$206,$B36,'Avaliação'!$E$7:$E$206),2),"")) | F36: {=IF($B36="","",IFERROR(INDEX('Avaliação'!$E$7:$E$206,MATCH($B36,'Avaliação'!$C$7:$C$206,0)),""))} | G36: =IF($B36="","",IF($D36<>2,"",IF($F36="","",ROUND(SUMIF('Avaliação'!$C$7:$C$206,$B36,'Avaliação'!$E$7:$E$206)-$F36,2)))) | H36: =IF($B36="","",IF(OR($F36="",$G36=""),"",ROUND(ABS($F36-$G36),2))) | I36: =IF($B36="","",IF($D36<2,"⚠ falta 2º avaliador",IF($D36>2,"⚠ mais de 2 avaliações — conferir",IF(AND(ISNUMBER($H36),$H36>1),"⚠ divergência > 1,0 — média suspensa, calibrar","OK")))) | M36: =IF($E36="","",COUNTIF($E$5:$E$64,">"&$E36)+1) | N36: =IF($B36="","",IF(Entrevista!$H36="","",Entrevista!$H36)) | O36: =IF($B36="","",IF(Entrevista!$L36="","",Entrevista!$L36))
A37: =IF($B37="","",ROW()-4) | D37: =IF($B37="","",COUNTIFS('Avaliação'!$C$7:$C$206,$B37,'Avaliação'!$E$7:$E$206,">=0")) | E37: =IF($B37="","",IFERROR(ROUND(AVERAGEIF('Avaliação'!$C$7:$C$206,$B37,'Avaliação'!$E$7:$E$206),2),"")) | F37: {=IF($B37="","",IFERROR(INDEX('Avaliação'!$E$7:$E$206,MATCH($B37,'Avaliação'!$C$7:$C$206,0)),""))} | G37: =IF($B37="","",IF($D37<>2,"",IF($F37="","",ROUND(SUMIF('Avaliação'!$C$7:$C$206,$B37,'Avaliação'!$E$7:$E$206)-$F37,2)))) | H37: =IF($B37="","",IF(OR($F37="",$G37=""),"",ROUND(ABS($F37-$G37),2))) | I37: =IF($B37="","",IF($D37<2,"⚠ falta 2º avaliador",IF($D37>2,"⚠ mais de 2 avaliações — conferir",IF(AND(ISNUMBER($H37),$H37>1),"⚠ divergência > 1,0 — média suspensa, calibrar","OK")))) | M37: =IF($E37="","",COUNTIF($E$5:$E$64,">"&$E37)+1) | N37: =IF($B37="","",IF(Entrevista!$H37="","",Entrevista!$H37)) | O37: =IF($B37="","",IF(Entrevista!$L37="","",Entrevista!$L37))
... A64: =IF($B64="","",ROW()-4) | D64: =IF($B64="","",COUNTIFS('Avaliação'!$C$7:$C$206,$B64,'Avaliação'!$E$7:$E$206,">=0")) | E64: =IF($B64="","",IFERROR(ROUND(AVERAGEIF('Avaliação'!$C$7:$C$206,$B64,'Avaliação'!$E$7:$E$206),2),"")) | F64: {=IF($B64="","",IFERROR(INDEX('Avaliação'!$E$7:$E$206,MATCH($B64,'Avaliação'!$C$7:$C$206,0)),""))} | G64: =IF($B64="","",IF($D64<>2,"",IF($F64="","",ROUND(SUMIF('Avaliação'!$C$7:$C$206,$B64,'Avaliação'!$E$7:$E$206)-$F64,2)))) | H64: =IF($B64="","",IF(OR($F64="",$G64=""),"",ROUND(ABS($F64-$G64),2))) | I64: =IF($B64="","",IF($D64<2,"⚠ falta 2º avaliador",IF($D64>2,"⚠ mais de 2 avaliações — conferir",IF(AND(ISNUMBER($H64),$H64>1),"⚠ divergência > 1,0 — média suspensa, calibrar","OK")))) | M64: =IF($E64="","",COUNTIF($E$5:$E$64,">"&$E64)+1) | N64: =IF($B64="","",IF(Entrevista!$H64="","",Entrevista!$H64)) | O64: =IF($B64="","",IF(Entrevista!$L64="","",Entrevista!$L64))
B66: NOTA FINAL = média das notas dos dois avaliadores (6,0 e 7,0 -> 6,50). Se a diferença passar de 1,0, a média fica suspensa: conversem e refaçam o critério que divergiu.
B67: FLAG: não soma nem subtrai ponto e nunca elimina. Ela (i) obriga uma pergunta específica na entrevista e (ii) só desempata entre candidatos a menos de 0,3 ponto um do outro.
B68: HORAS/SEM: o que o candidato declarou no formulário. Em 2025.2 a mediana foi 8h (de 4 a 40). Abaixo de 6h acende vermelho — é conversa de entrevista, não corte.
B69: ENTREVISTA: as duas últimas colunas vêm da aba Entrevista, não se digita aqui. 'Não OK' na checagem de propriedade é VETO — derruba independentemente da nota.
B70: NOTA AMARELA = provisória: veio de UM avaliador só. Ela entra no ranking normalmente, mas não é comparável com as médias de dois — carrega inteira a severidade de quem corrigiu (0,89 pt de amplitude entre avaliadores no PS 2026-1S). Não feche corte com amarelo na lista.

Sheet Entrevista
B2: ENTREVISTA — nesta versão NÃO pontua. Ela veta, desempata e registra.
B3: ⚠ A entrevista não é formalidade. Em 2025.2 ela cortou 10 dos 23 convocados (43%): o 3º colocado (8,15) foi cortado e o 20º (5,42) foi aprovado. Em 2026.1 não sobrou registro nenhum do que ela decidiu. Preencher esta aba é o mínimo para a próxima gestão saber o que aconteceu aqui.
A4: # | B4: Candidato(a) | C4: Nome | D4: Nota do case | E4: Flag | F4: Entrevistador(es) | G4: Data | H4: Refez a conta ao vivo? | I4: Qual conta foi pedida | J4: Pergunta da flag + resposta | K4: Observações da entrevista | L4: Decisão | M4: Motivo da decisão
A5: =IF($B5="","",ROW()-4) | D5: =IF($B5="","",Consolidado!$E5) | E5: =IF($B5="","",Consolidado!$J5)
A6: =IF($B6="","",ROW()-4) | D6: =IF($B6="","",Consolidado!$E6) | E6: =IF($B6="","",Consolidado!$J6)
A7: =IF($B7="","",ROW()-4) | D7: =IF($B7="","",Consolidado!$E7) | E7: =IF($B7="","",Consolidado!$J7)
A8: =IF($B8="","",ROW()-4) | D8: =IF($B8="","",Consolidado!$E8) | E8: =IF($B8="","",Consolidado!$J8)
A9: =IF($B9="","",ROW()-4) | D9: =IF($B9="","",Consolidado!$E9) | E9: =IF($B9="","",Consolidado!$J9)
A10: =IF($B10="","",ROW()-4) | D10: =IF($B10="","",Consolidado!$E10) | E10: =IF($B10="","",Consolidado!$J10)
A11: =IF($B11="","",ROW()-4) | D11: =IF($B11="","",Consolidado!$E11) | E11: =IF($B11="","",Consolidado!$J11)
A12: =IF($B12="","",ROW()-4) | D12: =IF($B12="","",Consolidado!$E12) | E12: =IF($B12="","",Consolidado!$J12)
A13: =IF($B13="","",ROW()-4) | D13: =IF($B13="","",Consolidado!$E13) | E13: =IF($B13="","",Consolidado!$J13)
A14: =IF($B14="","",ROW()-4) | D14: =IF($B14="","",Consolidado!$E14) | E14: =IF($B14="","",Consolidado!$J14)
A15: =IF($B15="","",ROW()-4) | D15: =IF($B15="","",Consolidado!$E15) | E15: =IF($B15="","",Consolidado!$J15)
A16: =IF($B16="","",ROW()-4) | D16: =IF($B16="","",Consolidado!$E16) | E16: =IF($B16="","",Consolidado!$J16)
... A25: =IF($B25="","",ROW()-4) | D25: =IF($B25="","",Consolidado!$E25) | E25: =IF($B25="","",Consolidado!$J25)
A26: =IF($B26="","",ROW()-4) | B26: =IF(Consolidado!$B26="","",Consolidado!$B26) | D26: =IF($B26="","",Consolidado!$E26) | E26: =IF($B26="","",Consolidado!$J26)
A27: =IF($B27="","",ROW()-4) | B27: =IF(Consolidado!$B27="","",Consolidado!$B27) | D27: =IF($B27="","",Consolidado!$E27) | E27: =IF($B27="","",Consolidado!$J27)
A28: =IF($B28="","",ROW()-4) | B28: =IF(Consolidado!$B28="","",Consolidado!$B28) | D28: =IF($B28="","",Consolidado!$E28) | E28: =IF($B28="","",Consolidado!$J28)
